Workbook
Name NativeTimeline_sale_date: #N/A
Name Slicer_category: #N/A
Name Slicer_channel: #N/A
Name Slicer_customer_type: #N/A

Sheet fashion_store_campaigns
A1: campaign_id | B1: campaign_name | C1: start_date | D1: end_date | E1: channel | F1: discount_type | G1: discount_value | H1: revenue
A2: 1 | B2: Spring Flash Sale | C2: 45748 | D2: 45754 | E2: Email | F2: Percentage | G2: 10
A3: 2 | B3: Easter Promotion | C3: 45755 | D3: 45762 | E3: Social Media | F3: Fixed | G3: 10
A4: 3 | B4: Mother's Day Campaign | C4: 45778 | D4: 45786 | E4: Email | F4: Percentage | G4: 25
A5: 4 | B5: Mid-Season Clearance | C5: 45787 | D5: 45796 | E5: App Mobile | F5: Percentage | G5: 30
A6: 5 | B6: TIVA Week | C6: 45797 | D6: 45808 | E6: Social Media | F6: Percentage | G6: 30
A7: 6 | B7: June Price Drop | C7: 45809 | D7: 45817 | E7: Website Banner | F7: Percentage | G7: 10
A8: 7 | B8: Early Summer Deals | C8: 45818 | D8: 45825 | E8: Email | F8: Fixed | G8: 12

Sheet fashion_store_channels
A1: channel | B1: description
A2: E-commerce | B2: Official online store
A3: App Mobile | B3: Brand mobile app

Sheet fashion_store_customers
A1: customer_id | B1: country | C1: age_range | D1: signup_date
A2: 1 | B2: France | C2: 56-65 | D2: 45771
A3: 2 | B3: France | C3: 36-45 | D3: 45712
A4: 3 | B4: Netherlands | C4: 46-55 | D4: 45394
A5: 4 | B5: Italy | C5: 36-45 | D5: 45727
A6: 5 | B6: Spain | C6: 26-35 | D6: 45773
A7: 6 | B7: Spain | C7: 46-55 | D7: 45640
A8: 7 | B8: France | C8: 46-55 | D8: 45562
A9: 8 | B9: Netherlands | C9: 46-55 | D9: 45398
A10: 9 | B10: Spain | C10: 46-55 | D10: 45723
A11: 10 | B11: Germany | C11: 16-25 | D11: 45363
A12: 11 | B12: France | C12: 16-25 | D12: 45480
A13: 12 | B13: Germany | C13: 46-55 | D13: 45819
... A1001: 1000 | B1001: Spain | C1001: 56-65 | D1001: 45297

Sheet fashion_store_products
A1: product_id | B1: product_name | C1: category | D1: brand | E1: color | F1: size | G1: catalog_price | H1: cost_price | I1: gender
A2: 1 | B2: Soft Wrap Dress | C2: Dresses | D2: Tiva | E2: Green | F2: S | G2: 40.41 | H2: 20.7 | I2: Female
A3: 2 | B3: Soft Wrap Tee | C3: T-Shirts | D3: Tiva | E3: White | F3: S | G3: 78.45 | H3: 53.76 | I3: Female
A4: 3 | B4: Soft Linen Tee | C4: T-Shirts | D4: Tiva | E4: Green | F4: XL | G4: 23.9 | H4: 14.81 | I4: Female
A5: 4 | B5: Soft Ribbed Tee | C5: T-Shirts | D5: Tiva | E5: White | F5: S | G5: 60 | H5: 34.78 | I5: Female
A6: 5 | B6: Soft Wrap Trousers | C6: Pants | D6: Tiva | E6: Blue | F6: M | G6: 36.84 | H6: 16.46 | I6: Female
A7: 6 | B7: Soft Wrap Shoes | C7: Shoes | D7: Tiva | E7: Green | F7: S | G7: 70.86 | H7: 31.66 | I7: Female
A8: 7 | B8: Soft Linen Dress | C8: Dresses | D8: Tiva | E8: White | F8: M | G8: 57.66 | H8: 24.07 | I8: Female
A9: 8 | B9: Soft Linen Trousers | C9: Pants | D9: Tiva | E9: Green | F9: M | G9: 50.91 | H9: 33.59 | I9: Female
A10: 9 | B10: Soft Linen Shoes | C10: Shoes | D10: Tiva | E10: Red | F10: L | G10: 40.5 | H10: 23.5 | I10: Female
A11: 10 | B11: Soft Ribbed Trousers | C11: Pants | D11: Tiva | E11: Black | F11: L | G11: 79.7 | H11: 48.81 | I11: Female
A12: 11 | B12: Soft Ribbed Shoes | C12: Shoes | D12: Tiva | E12: Green | F12: M | G12: 51.09 | H12: 20.75 | I12: Female
A13: 12 | B13: Soft Ribbed Dress | C13: Dresses | D13: Tiva | E13: Red | F13: XL | G13: 44.77 | H13: 30.93 | I13: Female
... A501: 500 | B501: Dresses Drop 9 | C501: Dresses | D501: Tiva | E501: White | F501: XS | G501: 38.03 | H501: 26.46 | I501: Female

Sheet fashion_store_sales
A1: sale_id | B1: channel | C1: discounted | D1: total_amount | E1: sale_date | F1: customer_id | G1: country | H1: weekday | I1: revenue | J1: counter | K1: age_range | L1: sighnup_date | M1: customer_tenure | N1: customer_type | O1: category
A2: 10 | B2: E-commerce | C2: 0 | D2: 299.7 | E2: 45798 | F2: 195 | G2: France | H2: =TEXT(sales[[#This Row],[sale_date]],"dddd") -> Wednesday | I2: =_xlfn.XLOOKUP(A2,salesitems[sale_id],salesitems[revenue],0) -> 59.92 | J2: 1 | K2: =_xlfn.XLOOKUP(F2,customers[customer_id],customers[age_range]) -> 56-65 | L2: =_xlfn.XLOOKUP(F2,customers[customer_id],customers[signup_date]) -> 45716 | M2: =sales[[#This Row],[sale_date]]-sales[[#This Row],[sighnup_date]] -> 82 | N2: =IF(M2<0,"data issue",IF(M2<=90,"new customer","existing customer")) -> new customer | O2: =_xlfn.XLOOKUP(A2,salesitems[sale_id],salesitems[category]) -> T-Shirts
A3: 100 | B3: App Mobile | C3: 0 | D3: 681.05 | E3: 45768 | F3: 518 | G3: Germany | H3: =TEXT(sales[[#This Row],[sale_date]],"dddd") -> Monday | I3: =_xlfn.XLOOKUP(A3,salesitems[sale_id],salesitems[revenue],0) -> 261.4 | J3: 1 | K3: =_xlfn.XLOOKUP(F3,customers[customer_id],customers[age_range]) -> 46-55 | L3: =_xlfn.XLOOKUP(F3,customers[customer_id],customers[signup_date]) -> 45745 | M3: =sales[[#This Row],[sale_date]]-sales[[#This Row],[sighnup_date]] -> 23 | N3: =IF(M3<0,"data issue",IF(M3<=90,"new customer","existing customer")) -> new customer | O3: =_xlfn.XLOOKUP(A3,salesitems[sale_id],salesitems[category]) -> Sleepwear
A4: 1000 | B4: E-commerce | C4: 0 | D4: 324.5 | E4: 45797 | F4: 439 | G4: Germany | H4: =TEXT(sales[[#This Row],[sale_date]],"dddd") -> Tuesday | I4: =_xlfn.XLOOKUP(A4,salesitems[sale_id],salesitems[revenue],0) -> 91.5 | J4: 1 | K4: =_xlfn.XLOOKUP(F4,customers[customer_id],customers[age_range]) -> 36-45 | L4: =_xlfn.XLOOKUP(F4,customers[customer_id],customers[signup_date]) -> 45788 | M4: =sales[[#This Row],[sale_date]]-sales[[#This Row],[sighnup_date]] -> 9 | N4: =IF(M4<0,"data issue",IF(M4<=90,"new customer","existing customer")) -> new customer | O4: =_xlfn.XLOOKUP(A4,salesitems[sale_id],salesitems[category]) -> T-Shirts
A5: 1001 | B5: E-commerce | C5: 0 | D5: 287.85 | E5: 45752 | F5: 349 | G5: Germany | H5: =TEXT(sales[[#This Row],[sale_date]],"dddd") -> Saturday | I5: =_xlfn.XLOOKUP(A5,salesitems[sale_id],salesitems[revenue],0) -> 192.33 | J5: 1 | K5: =_xlfn.XLOOKUP(F5,customers[customer_id],customers[age_range]) -> 26-35 | L5: =_xlfn.XLOOKUP(F5,customers[customer_id],customers[signup_date]) -> 45736 | M5: =sales[[#This Row],[sale_date]]-sales[[#This Row],[sighnup_date]] -> 16 | N5: =IF(M5<0,"data issue",IF(M5<=90,"new customer","existing customer")) -> new customer | O5: =_xlfn.XLOOKUP(A5,salesitems[sale_id],salesitems[category]) -> Sleepwear
A6: 1003 | B6: App Mobile | C6: 0 | D6: 430.64 | E6: 45814 | F6: 727 | G6: Portugal | H6: =TEXT(sales[[#This Row],[sale_date]],"dddd") -> Friday | I6: =_xlfn.XLOOKUP(A6,salesitems[sale_id],salesitems[revenue],0) -> 218.44 | J6: 1 | K6: =_xlfn.XLOOKUP(F6,customers[customer_id],customers[age_range]) -> 26-35 | L6: =_xlfn.XLOOKUP(F6,customers[customer_id],customers[signup_date]) -> 45725 | M6: =sales[[#This Row],[sale_date]]-sales[[#This Row],[sighnup_date]] -> 89 | N6: =IF(M6<0,"data issue",IF(M6<=90,"new customer","existing customer")) -> new customer | O6: =_xlfn.XLOOKUP(A6,salesitems[sale_id],salesitems[category]) -> Pants
A7: 1004 | B7: App Mobile | C7: 0 | D7: 104.73 | E7: 45774 | F7: 983 | G7: Germany | H7: =TEXT(sales[[#This Row],[sale_date]],"dddd") -> Sunday | I7: =_xlfn.XLOOKUP(A7,salesitems[sale_id],salesitems[revenue],0) -> 53.48 | J7: 1 | K7: =_xlfn.XLOOKUP(F7,customers[customer_id],customers[age_range]) -> 36-45 | L7: =_xlfn.XLOOKUP(F7,customers[customer_id],customers[signup_date]) -> 45768 | M7: =sales[[#This Row],[sale_date]]-sales[[#This Row],[sighnup_date]] -> 6 | N7: =IF(M7<0,"data issue",IF(M7<=90,"new customer","existing customer")) -> new customer | O7: =_xlfn.XLOOKUP(A7,salesitems[sale_id],salesitems[category]) -> T-Shirts
A8: 1006 | B8: E-commerce | C8: 0 | D8: 249.21 | E8: 45782 | F8: 309 | G8: Spain | H8: =TEXT(sales[[#This Row],[sale_date]],"dddd") -> Monday | I8: =_xlfn.XLOOKUP(A8,salesitems[sale_id],salesitems[revenue],0) -> 53.7 | J8: 1 | K8: =_xlfn.XLOOKUP(F8,customers[customer_id],customers[age_range]) -> 46-55 | L8: =_xlfn.XLOOKUP(F8,customers[customer_id],customers[signup_date]) -> 45765 | M8: =sales[[#This Row],[sale_date]]-sales[[#This Row],[sighnup_date]] -> 17 | N8: =IF(M8<0,"data issue",IF(M8<=90,"new customer","existing customer")) -> new customer | O8: =_xlfn.XLOOKUP(A8,salesitems[sale_id],salesitems[category]) -> T-Shirts
A9: 1007 | B9: App Mobile | C9: 0 | D9: 437.52 | E9: 45763 | F9: 53 | G9: Italy | H9: =TEXT(sales[[#This Row],[sale_date]],"dddd") -> Wednesday | I9: =_xlfn.XLOOKUP(A9,salesitems[sale_id],salesitems[revenue],0) -> 174.27 | J9: 1 | K9: =_xlfn.XLOOKUP(F9,customers[customer_id],customers[age_range]) -> 46-55 | L9: =_xlfn.XLOOKUP(F9,customers[customer_id],customers[signup_date]) -> 45789 | M9: =sales[[#This Row],[sale_date]]-sales[[#This Row],[sighnup_date]] -> -26 | N9: =IF(M9<0,"data issue",IF(M9<=90,"new customer","existing customer")) -> data issue | O9: =_xlfn.XLOOKUP(A9,salesitems[sale_id],salesitems[category]) -> Pants
A10: 1008 | B10: App Mobile | C10: 0 | D10: 386.92 | E10: 45801 | F10: 593 | G10: France | H10: =TEXT(sales[[#This Row],[sale_date]],"dddd") -> Saturday | I10: =_xlfn.XLOOKUP(A10,salesitems[sale_id],salesitems[revenue],0) -> 210.6 | J10: 1 | K10: =_xlfn.XLOOKUP(F10,customers[customer_id],customers[age_range]) -> 26-35 | L10: =_xlfn.XLOOKUP(F10,customers[customer_id],customers[signup_date]) -> 45727 | M10: =sales[[#This Row],[sale_date]]-sales[[#This Row],[sighnup_date]] -> 74 | N10: =IF(M10<0,"data issue",IF(M10<=90,"new customer","existing customer")) -> new customer | O10: =_xlfn.XLOOKUP(A10,salesitems[sale_id],salesitems[category]) -> Dresses
A11: 1011 | B11: App Mobile | C11: 0 | D11: 212.87 | E11: 45764 | F11: 161 | G11: Spain | H11: =TEXT(sales[[#This Row],[sale_date]],"dddd") -> Thursday | I11: =_xlfn.XLOOKUP(A11,salesitems[sale_id],salesitems[revenue],0) -> 80.24 | J11: 1 | K11: =_xlfn.XLOOKUP(F11,customers[customer_id],customers[age_range]) -> 36-45 | L11: =_xlfn.XLOOKUP(F11,customers[customer_id],customers[signup_date]) -> 45742 | M11: =sales[[#This Row],[sale_date]]-sales[[#This Row],[sighnup_date]] -> 22 | N11: =IF(M11<0,"data issue",IF(M11<=90,"new customer","existing customer")) -> new customer | O11: =_xlfn.XLOOKUP(A11,salesitems[sale_id],salesitems[category]) -> T-Shirts
A12: 1013 | B12: App Mobile | C12: 0 | D12: 178.68 | E12: 45777 | F12: 296 | G12: France | H12: =TEXT(sales[[#This Row],[sale_date]],"dddd") -> Wednesday | I12: =_xlfn.XLOOKUP(A12,salesitems[sale_id],salesitems[revenue],0) -> 72.58 | J12: 1 | K12: =_xlfn.XLOOKUP(F12,customers[customer_id],customers[age_range]) -> 16-25 | L12: =_xlfn.XLOOKUP(F12,customers[customer_id],customers[signup_date]) -> 45810 | M12: =sales[[#This Row],[sale_date]]-sales[[#This Row],[sighnup_date]] -> -33 | N12: =IF(M12<0,"data issue",IF(M12<=90,"new customer","existing customer")) -> data issue | O12: =_xlfn.XLOOKUP(A12,salesitems[sale_id],salesitems[category]) -> Shoes
A13: 1014 | B13: E-commerce | C13: 0 | D13: 175.37 | E13: 45793 | F13: 578 | G13: Germany | H13: =TEXT(sales[[#This Row],[sale_date]],"dddd") -> Friday | I13: =_xlfn.XLOOKUP(A13,salesitems[sale_id],salesitems[revenue],0) -> 68.47 | J13: 1 | K13: =_xlfn.XLOOKUP(F13,customers[customer_id],customers[age_range]) -> 16-25 | L13: =_xlfn.XLOOKUP(F13,customers[customer_id],customers[signup_date]) -> 45750 | M13: =sales[[#This Row],[sale_date]]-sales[[#This Row],[sighnup_date]] -> 43 | N13: =IF(M13<0,"data issue",IF(M13<=90,"new customer","existing customer")) -> new customer | O13: =_xlfn.XLOOKUP(A13,salesitems[sale_id],salesitems[category]) -> Shoes
... A906: 999 | B906: E-commerce | C906: 0 | D906: 109.62 | E906: 45824 | F906: 416 | G906: France | H906: =TEXT(sales[[#This Row],[sale_date]],"dddd") -> Monday | I906: =_xlfn.XLOOKUP(A906,salesitems[sale_id],salesitems[revenue],0) -> 39.22 | J906: 1 | K906: =_xlfn.XLOOKUP(F906,customers[customer_id],customers[age_range]) -> 46-55 | L906: =_xlfn.XLOOKUP(F906,customers[customer_id],customers[signup_date]) -> 45748 | M906: =sales[[#This Row],[sale_date]]-sales[[#This Row],[sighnup_date]] -> 76 | N906: =IF(M906<0,"data issue",IF(M906<=90,"new customer","existing customer")) -> new customer | O906: =_xlfn.XLOOKUP(A906,salesitems[sale_id],salesitems[category]) -> Pants

Sheet fashion_store_salesitems
A1: item_id | B1: sale_id | C1: product_id | D1: quantity | E1: original_price | F1: unit_price | G1: discount_applied | H1: discount_percent | I1: discounted | J1: item_total | K1: sale_date | L1: channel | M1: channel_campaigns | N1: revenue | O1: product_name | P1: category
A2: 2270 | B2: 658 | C2: 403 | D2: 1 | E2: 81.8 | F2: 81.8 | G2: 0 | H2: 0 | I2: 0 | J2: 81.8 | K2: 45824 | L2: App Mobile | M2: App Mobile | N2: =salesitems[[#This Row],[quantity]]*salesitems[[#This Row],[unit_price]] -> 81.8 | O2: =_xlfn.XLOOKUP(salesitems[[#This Row],[product_id]],products[product_id],products[product_name]) -> Elegant Satin Dress | P2: =_xlfn.XLOOKUP(salesitems[[#This Row],[product_id]],fashion_store_products!A:A,fashion_store_products!C:C) -> Dresses
A3: 1170 | B3: 336 | C3: 284 | D3: 1 | E3: 81.79 | F3: 81.79 | G3: 0 | H3: 0 | I3: 0 | J3: 81.79 | K3: 45825 | L3: E-commerce | M3: Website Banner | N3: =salesitems[[#This Row],[quantity]]*salesitems[[#This Row],[unit_price]] -> 81.79 | O3: =_xlfn.XLOOKUP(salesitems[[#This Row],[product_id]],products[product_id],products[product_name]) -> Essential Cotton Shoes | P3: =_xlfn.XLOOKUP(salesitems[[#This Row],[product_id]],fashion_store_products!A:A,fashion_store_products!C:C) -> Shoes
A4: 2496 | B4: 1255 | C4: 71 | D4: 1 | E4: 80.76 | F4: 80.76 | G4: 0 | H4: 0 | I4: 0 | J4: 80.76 | K4: 45763 | L4: App Mobile | M4: App Mobile | N4: =salesitems[[#This Row],[quantity]]*salesitems[[#This Row],[unit_price]] -> 80.76 | O4: =_xlfn.XLOOKUP(salesitems[[#This Row],[product_id]],products[product_id],products[product_name]) -> Modern Ribbed Trousers | P4: =_xlfn.XLOOKUP(salesitems[[#This Row],[product_id]],fashion_store_products!A:A,fashion_store_products!C:C) -> Pants
A5: 1273 | B5: 331 | C5: 98 | D5: 1 | E5: 78.52 | F5: 78.52 | G5: 0 | H5: 0 | I5: 0 | J5: 78.52 | K5: 45783 | L5: App Mobile | M5: App Mobile | N5: =salesitems[[#This Row],[quantity]]*salesitems[[#This Row],[unit_price]] -> 78.52 | O5: =_xlfn.XLOOKUP(salesitems[[#This Row],[product_id]],products[product_id],products[product_name]) -> Modern Boxy Shoes | P5: =_xlfn.XLOOKUP(salesitems[[#This Row],[product_id]],fashion_store_products!A:A,fashion_store_products!C:C) -> Shoes
A6: 1829 | B6: 1079 | C6: 98 | D6: 1 | E6: 78.52 | F6: 78.52 | G6: 0 | H6: 0 | I6: 0 | J6: 78.52 | K6: 45823 | L6: App Mobile | M6: App Mobile | N6: =salesitems[[#This Row],[quantity]]*salesitems[[#This Row],[unit_price]] -> 78.52 | O6: =_xlfn.XLOOKUP(salesitems[[#This Row],[product_id]],products[product_id],products[product_name]) -> Modern Boxy Shoes | P6: =_xlfn.XLOOKUP(salesitems[[#This Row],[product_id]],fashion_store_products!A:A,fashion_store_products!C:C) -> Shoes
A7: 3221 | B7: 478 | C7: 98 | D7: 1 | E7: 78.52 | F7: 78.52 | G7: 0 | H7: 0 | I7: 0 | J7: 78.52 | K7: 45761 | L7: App Mobile | M7: App Mobile | N7: =salesitems[[#This Row],[quantity]]*salesitems[[#This Row],[unit_price]] -> 78.52 | O7: =_xlfn.XLOOKUP(salesitems[[#This Row],[product_id]],products[product_id],products[product_name]) -> Modern Boxy Shoes | P7: =_xlfn.XLOOKUP(salesitems[[#This Row],[product_id]],fashion_store_products!A:A,fashion_store_products!C:C) -> Shoes
A8: 2442 | B8: 1082 | C8: 257 | D8: 1 | E8: 77.9 | F8: 77.9 | G8: 0 | H8: 0 | I8: 0 | J8: 77.9 | K8: 45753 | L8: App Mobile | M8: App Mobile | N8: =salesitems[[#This Row],[quantity]]*salesitems[[#This Row],[unit_price]] -> 77.9 | O8: =_xlfn.XLOOKUP(salesitems[[#This Row],[product_id]],products[product_id],products[product_name]) -> Relaxed Crew Shoes | P8: =_xlfn.XLOOKUP(salesitems[[#This Row],[product_id]],fashion_store_products!A:A,fashion_store_products!C:C) -> Shoes
A9: 730 | B9: 747 | C9: 413 | D9: 1 | E9: 76.15 | F9: 76.15 | G9: 0 | H9: 0 | I9: 0 | J9: 76.15 | K9: 45768 | L9: App Mobile | M9: App Mobile | N9: =salesitems[[#This Row],[quantity]]*salesitems[[#This Row],[unit_price]] -> 76.15 | O9: =_xlfn.XLOOKUP(salesitems[[#This Row],[product_id]],products[product_id],products[product_name]) -> Elegant Satin Shoes | P9: =_xlfn.XLOOKUP(salesitems[[#This Row],[product_id]],fashion_store_products!A:A,fashion_store_products!C:C) -> Shoes
A10: 2917 | B10: 258 | C10: 392 | D10: 1 | E10: 75.47 | F10: 75.47 | G10: 0 | H10: 0 | I10: 0 | J10: 75.47 | K10: 45806 | L10: E-commerce | M10: Website Banner | N10: =salesitems[[#This Row],[quantity]]*salesitems[[#This Row],[unit_price]] -> 75.47 | O10: =_xlfn.XLOOKUP(salesitems[[#This Row],[product_id]],products[product_id],products[product_name]) -> Elegant Wrap Shoes | P10: =_xlfn.XLOOKUP(salesitems[[#This Row],[product_id]],fashion_store_products!A:A,fashion_store_products!C:C) -> Shoes
A11: 3142 | B11: 1144 | C11: 392 | D11: 1 | E11: 75.47 | F11: 75.47 | G11: 0 | H11: 0 | I11: 0 | J11: 75.47 | K11: 45797 | L11: E-commerce | M11: Website Banner | N11: =salesitems[[#This Row],[quantity]]*salesitems[[#This Row],[unit_price]] -> 75.47 | O11: =_xlfn.XLOOKUP(salesitems[[#This Row],[product_id]],products[product_id],products[product_name]) -> Elegant Wrap Shoes | P11: =_xlfn.XLOOKUP(salesitems[[#This Row],[product_id]],fashion_store_products!A:A,fashion_store_products!C:C) -> Shoes
A12: 209 | B12: 644 | C12: 224 | D12: 1 | E12: 75.4 | F12: 75.4 | G12: 0 | H12: 0 | I12: 0 | J12: 75.4 | K12: 45751 | L12: E-commerce | M12: Website Banner | N12: =salesitems[[#This Row],[quantity]]*salesitems[[#This Row],[unit_price]] -> 75.4 | O12: =_xlfn.XLOOKUP(salesitems[[#This Row],[product_id]],products[product_id],products[product_name]) -> Relaxed Linen Dress | P12: =_xlfn.XLOOKUP(salesitems[[#This Row],[product_id]],fashion_store_products!A:A,fashion_store_products!C:C) -> Dresses
A13: 1138 | B13: 991 | C13: 224 | D13: 1 | E13: 75.4 | F13: 75.4 | G13: 0 | H13: 0 | I13: 0 | J13: 75.4 | K13: 45767 | L13: App Mobile | M13: App Mobile | N13: =salesitems[[#This Row],[quantity]]*salesitems[[#This Row],[unit_price]] -> 75.4 | O13: =_xlfn.XLOOKUP(salesitems[[#This Row],[product_id]],products[product_id],products[product_name]) -> Relaxed Linen Dress | P13: =_xlfn.XLOOKUP(salesitems[[#This Row],[product_id]],fashion_store_products!A:A,fashion_store_products!C:C) -> Dresses
... A2254: 685 | B2254: 724 | C2254: 346 | D2254: 5 | E2254: 15.31 | F2254: 15.31 | G2254: 0 | H2254: 0 | I2254: 0 | J2254: 76.55 | K2254: 45807 | L2254: E-commerce | M2254: Website Banner | N2254: =salesitems[[#This Row],[quantity]]*salesitems[[#This Row],[unit_price]] -> 76.55 | O2254: =_xlfn.XLOOKUP(salesitems[[#This Row],[product_id]],products[product_id],products[product_name]) -> Relaxed Crew Trousers | P2254: =_xlfn.XLOOKUP(salesitems[[#This Row],[product_id]],fashion_store_products!A:A,fashion_store_products!C:C) -> Pants

Sheet fashion_store_stock
A1: country | B1: product_id | C1: stock_quantity
A2: France | B2: 1 | C2: 61
A3: France | B3: 2 | C3: 24
A4: France | B4: 3 | C4: 81
A5: France | B5: 4 | C5: 70
A6: France | B6: 5 | C6: 30
A7: France | B7: 6 | C7: 92
A8: France | B8: 7 | C8: 96
A9: France | B9: 8 | C9: 84
A10: France | B10: 9 | C10: 84
A11: France | B11: 10 | C11: 97
A12: France | B12: 11 | C12: 3
A13: France | B13: 12 | C13: 12
... A1001: Germany | B1001: 500 | C1001: 1

Sheet kPI_sheet
A1: sale_KPI:
A2: Metric | B2: Value
A3: Total_Revenue | B3: =SUM(fashion_store_salesitems!N:N) -> 324236.87
A4: Total_Order | B4: =COUNTA(_xlfn.UNIQUE(fashion_store_sales!A:A)) -> 907
A5: Total Customer | B5: =COUNTA(_xlfn.UNIQUE(sales[customer_id])) -> 580
A6: Total_Item_Sold | B6: =SUM(salesitems[quantity]) -> 6715
A7: Average_Order_Value | B7: =B3/B4 -> 357.48277
A8: Avg Items Per Order | B8: =B6/B4 -> 7.4035281
A9: Best Month | B9: May
A10: Best Weekday | B10: Tuesday
A11: Mom Growth | B11: =GETPIVOTDATA("Mom Growth",monthly_revenue_pivot!$A$3,"Months (sale_date)",6) -> -0.63663917
A13: customer_KPI:
A14: Metric | B14: Value
A15: top customer(revenue) | B15: 798
A16: top customer revenue | B16: 776.8
A17: avg AOV(top 10 customer) | B17: 275.81533
A18: top country(customer) | B18: Germany
A19: top channel(customer) | B19: E-commerce
A21: channel_performance_KPI:
A22: Metric | B22: Value
A23: Best_channel(Revenue) | B23: E-commerce
A24: Best_channel(Orders) | B24: E-commerce
A26: category_performance_KPI:
A27: Metric | B27: value
A28: top category(revenue) | B28: Shoes
A29: revenue_of_top_category | B29: 70074.01
A31: stock_KPI:
A32: Metric | B32: Value
A33: revenue_France | B33: =GETPIVOTDATA("Sum of revenue",country_sales_pivot!$A$3,"country","France") -> 19498.7
A34: revenue_Germany | B34: =GETPIVOTDATA("Sum of revenue",country_sales_pivot!$A$3,"country","Germany") -> 21266.54
A35: orders_France | B35: =GETPIVOTDATA("Count of sale_id",country_sales_pivot!$A$3,"country","France") -> 199
A36: orders_Germany | B36: =GETPIVOTDATA("Count of sale_id",country_sales_pivot!$A$3,"country","Germany") -> 212
A37: stock_quantity_France | B37: =country_sales_pivot!D4 -> 24076
A38: stock_quantity_Germany | B38: =country_sales_pivot!D5 -> 499
A39: sales_to_stock_ratio_France | B39: =B33/B37 -> 0.80988121
A40: sales_to_stock_ratio_Germany | B40: =B34/B38 -> 42.618317
A41: orders_to_stock_ratio_France | B41: =B35/B37 -> 0.0082654926
A42: orders_to_stock_ratio_Germany | B42: =B36/B38 -> 0.4248497
A43: best stock efficiency country | B43: Germany
A44: revenue share_France | B44: =B33/(B33+B34) -> 0.47831682
...

Sheet monthly_revenue_pivot
A3: Row Labels | B3: Sum of revenue | C3: Mom Growth | D3: Mom Growth
A4: Apr | B4: 132588.01
A5: May | B5: 143471.57 | C5: 0.082085552 | D5: =(B5-B4)/B4 -> 0.082085552
A6: Jun | B6: 48177.29 | C6: -0.63663917 | D6: =(B6-B5)/B5 -> -0.66420323
A7: Grand Total | B7: 324236.87

Sheet weekday revenue pivot
A3: Row Labels | B3: Sum of revenue
A4: Sunday | B4: 13958.4
A5: Monday | B5: 14271.91
A6: Tuesday | B6: 15231.39
A7: Wednesday | B7: 10693.99
A8: Thursday | B8: 10932.51
A9: Friday | B9: 13002.73
A10: Saturday | B10: 13310.96
A11: Grand Total | B11: 91401.89

Sheet campaign_perfomance_pivot
A3: Row Labels | B3: Sum of revenue | C3: Count of sale_id
A4: App Mobile | B4: 43685.39 | C4: 432
A5: E-commerce | B5: 47716.5 | C5: 473
A6: Grand Total | B6: 91401.89 | C6: 905

Sheet campaign_by_channel_pivot
A3: Row Labels | B3: Count of campaign_id | C3: Average of discount_value
A4: App Mobile | B4: 1 | C4: 30
A5: Email | B5: 3 | C5: 15.666667
A6: Social Media | B6: 2 | C6: 20
A7: Website Banner | B7: 1 | C7: 10
A8: Grand Total | B8: 7 | C8: 18.142857

Sheet channel_perfomance_pivot
A3: Row Labels | B3: Count of sale_id | C3: Sum of revenue
A4: App Mobile | B4: 432 | C4: 0.47794843
A5: E-commerce | B5: 473 | C5: 0.52205157
A6: Grand Total | B6: 905 | C6: 1

Sheet customer_revenue_pivot
A3: Row Labels | B3: Sum of revenue | C3: Count of sale_id | D3: Aov
A4: 1 | B4: 50.04 | C4: 1 | D4: 50.04
A5: 2 | B5: 352.32 | C5: 3 | D5: 117.44
A6: 5 | B6: 343 | C6: 2 | D6: 171.5
A7: 9 | B7: 158.28 | C7: 2 | D7: 79.14
A8: 12 | B8: 114.62 | C8: 1 | D8: 114.62
A9: 14 | B9: 43.06 | C9: 1 | D9: 43.06
A10: 15 | B10: 200.92 | C10: 2 | D10: 100.46
A11: 16 | B11: 170.68 | C11: 1 | D11: 170.68
A12: 17 | B12: 50.55 | C12: 1 | D12: 50.55
A13: 18 | B13: 154.89 | C13: 1 | D13: 154.89
A14: 19 | B14: 224.43 | C14: 1 | D14: 224.43
A15: 20 | B15: 245.37 | C15: 1 | D15: 245.37
... A583: 999 | B583: 224.16 | C583: 2 | D583: 112.08
A584: Grand Total | B584: 91401.89 | C584: 905 | D584: 100.99656

Sheet customer_country_pivot
A3: Row Labels | B3: Sum of revenue | C3: Count of sale_id
A4: Germany | B4: 21266.54 | C4: 212
A5: France | B5: 19498.7 | C5: 199
A6: Italy | B6: 17869.26 | C6: 170
A7: Netherlands | B7: 13299.84 | C7: 131
A8: Spain | B8: 11734.52 | C8: 113
A9: Portugal | B9: 7733.03 | C9: 80
A10: Grand Total | B10: 91401.89 | C10: 905

Sheet customer_channel_pivot
A3: Row Labels | B3: Sum of revenue | C3: Count of sale_id
A4: E-commerce | B4: 47716.5 | C4: 473
A5: App Mobile | B5: 43685.39 | C5: 432
A6: Grand Total | B6: 91401.89 | C6: 905

Sheet RFM_base
A3: customer_id | B3: last_purchase_date | C3: Monetary | D3: Frequency | E3: Recency
A4: 1 | B4: 45772 | C4: 50.04 | D4: 1 | E4: =TODAY()-B4 -> 269
A5: 2 | B5: 45803 | C5: 352.32 | D5: 3 | E5: =TODAY()-B5 -> 238
A6: 5 | B6: 45799 | C6: 343 | D6: 2 | E6: =TODAY()-B6 -> 242
A7: 9 | B7: 45802 | C7: 158.28 | D7: 2 | E7: =TODAY()-B7 -> 239
A8: 12 | B8: 45768 | C8: 114.62 | D8: 1 | E8: =TODAY()-B8 -> 273
A9: 14 | B9: 45776 | C9: 43.06 | D9: 1 | E9: =TODAY()-B9 -> 265
A10: 15 | B10: 45801 | C10: 200.92 | D10: 2 | E10: =TODAY()-B10 -> 240
A11: 16 | B11: 45771 | C11: 170.68 | D11: 1 | E11: =TODAY()-B11 -> 270
A12: 17 | B12: 45776 | C12: 50.55 | D12: 1 | E12: =TODAY()-B12 -> 265
A13: 18 | B13: 45804 | C13: 154.89 | D13: 1 | E13: =TODAY()-B13 -> 237
A14: 19 | B14: 45760 | C14: 224.43 | D14: 1 | E14: =TODAY()-B14 -> 281
A15: 20 | B15: 45821 | C15: 245.37 | D15: 1 | E15: =TODAY()-B15 -> 220
... A583: 999 | B583: 45814 | C583: 224.16 | D583: 2 | E583: =TODAY()-B583 -> 227
A584: Grand Total | B584: 45825 | C584: 91401.89 | D584: 905 | E584: =TODAY()-B584 -> 216

Sheet product_perfomance_pivot
A3: Row Labels | B3: Sum of revenue | C3: Sum of quantity
A4: Shoes | B4: 70074.01 | C4: 1400
A5: T-Shirts | B5: 69692.81 | C5: 1439
A6: Dresses | B6: 68390.73 | C6: 1451
A7: Sleepwear | B7: 62276.61 | C7: 1362
A8: Pants | B8: 53802.71 | C8: 1063
A9: Grand Total | B9: 324236.87 | C9: 6715

Sheet bottom_products_pivot
A3: Row Labels | B3: Sum of revenue | C3: Sum of quantity
A4: Soft Sleeveless Set | B4: 13.51 | C4: 1
A5: Tailored High-Waist Shoes | B5: 42.5 | C5: 1
A6: Classic Silk Dress | B6: 53.32 | C6: 1
A7: Elegant Sleeveless Dress | B7: 55.39 | C7: 1
A8: Soft Crew Shoes | B8: 57.48 | C8: 1
A9: Modern Crew Tee | B9: 67.37 | C9: 1
A10: Essential Cotton Trousers | B10: 70.82 | C10: 1
A11: Modern Sleeveless Dress | B11: 71.62 | C11: 2
A12: Relaxed Sleeveless Dress | B12: 81.26 | C12: 2
A13: Essential Sleeveless Trousers | B13: 86.19 | C13: 3
A14: Grand Total | B14: 599.46 | C14: 14

Sheet country_sales_pivot
A3: Row Labels | B3: Sum of revenue | C3: Count of sale_id | D3: stock_quantity
A4: France | B4: 19498.7 | C4: 199 | D4: =SUMIF(fashion_store_stock!A:A,"France",stock[stock_quantity]) -> 24076
A5: Germany | B5: 21266.54 | C5: 212 | D5: =SUMIF(fashion_store_stock!A:A,"Germany",stock[stock_quantity]) -> 499
A6: Grand Total | B6: 40765.24 | C6: 411

Sheet basket Analysis pivot
A3: Row Labels | B3: total items per sale | C3: product per sale | D3: average_items | E3: average_product
A4: 287 | B4: 15 | C4: 3 | D4: =AVERAGE(B4:B908) -> 7.4198895 | E4: =AVERAGE(C3:C908) -> 2.4895028
A5: 410 | B5: 15 | C5: 3
A6: 352 | B6: 15 | C6: 3
A7: 100 | B7: 15 | C7: 3
A8: 108 | B8: 15 | C8: 3
A9: 458 | B9: 14 | C9: 3
A10: 518 | B10: 14 | C10: 3
A11: 480 | B11: 14 | C11: 3
A12: 81 | B12: 14 | C12: 3
A13: 64 | B13: 14 | C13: 3
A14: 295 | B14: 14 | C14: 3
A15: 118 | B15: 14 | C15: 3
A16: 361 | B16: 14 | C16: 3
... A908: 868 | B908: 2 | C908: 2
A909: Grand Total | B909: 6715 | C909: 2253

Sheet time_analysis_pivot
A3: Row Labels | B3: Sum of revenue | C3: Count of sale_id | D3: average_monthly_revenue | E3: best_revenue_month | F3: peak_order_month
A4: 2025 | B4: 91401.89 | C4: 905 | D4: =AVERAGE(B5:B7) -> 30467.297 | E4: =_xlfn.XLOOKUP(MAX(B5:B7),B5:B7,A5:A7) -> May | F4: =_xlfn.XLOOKUP(MAX(C5:C7),C5:C7,A5:A7) -> May
A5: Apr | B5: 37751.68 | C5: 364
A6: May | B6: 39570.94 | C6: 403
A7: Jun | B7: 14079.27 | C7: 138
A8: Grand Total | B8: 91401.89 | C8: 905

Sheet customer_performance_pivot
A3: Row Labels | B3: Sum of revenue | C3: Count of sale_id
A4: data issue | B4: 6715.06 | C4: 73
A5: existing customer | B5: 15532.75 | C5: 160
A6: new customer | B6: 69154.08 | C6: 672
A7: Grand Total | B7: 91401.89 | C7: 905

Sheet age_range_performance_pivot
A3: Row Labels | B3: Sum of revenue | C3: Count of sale_id
A4: 26-35 | B4: 19502.44 | C4: 189
A5: 46-55 | B5: 18709.53 | C5: 176
A6: 16-25 | B6: 18425.14 | C6: 181
A7: 36-45 | B7: 18278.15 | C7: 188
A8: 56-65 | B8: 16486.63 | C8: 171
A9: Grand Total | B9: 91401.89 | C9: 905

Sheet age_range&customer_type
A3: Sum of revenue | B3: Column Labels
A4: Row Labels | B4: data issue | C4: existing customer | D4: new customer | E4: Grand Total
A5: 16-25 | B5: 1553.57 | C5: 2891.43 | D5: 13980.14 | E5: 18425.14
A6: 26-35 | B6: 1462.34 | C6: 4239.21 | D6: 13800.89 | E6: 19502.44
A7: 36-45 | B7: 1341.69 | C7: 3229.71 | D7: 13706.75 | E7: 18278.15
A8: 46-55 | B8: 1489.78 | C8: 1642.83 | D8: 15576.92 | E8: 18709.53
A9: 56-65 | B9: 867.68 | C9: 3529.57 | D9: 12089.38 | E9: 16486.63
A10: Grand Total | B10: 6715.06 | C10: 15532.75 | D10: 69154.08 | E10: 91401.89

Sheet General_Pivot
A3: Sum of revenue
A4: 91401.89

Sheet Dashboared
B1: Total Revenue | C1: Total Orders | D1: Total Customers | E1: Average Order VAlue
B2: =kPI_sheet!B3 -> 324236.87 | C2: =kPI_sheet!B4 -> 907 | D2: =kPI_sheet!B5 -> 580 | E2: =kPI_sheet!B7 -> 357.48277
